Workbook

Sheet Heinz-Kraft Merger
A1: Kraft Heinz Company | B1: In July of 2015 Heinz acquired all of the stock of Kraft in exchange for $42.855B worth of new Kraft Heinz stock.
A2: 2015 Acquisition of Kraft by Heinz | B2: In addition, the Kraft shareholders received a special cash dividend of $16.50 per share ($9.782B).
A3: In millions except per share data | B3: Total consideration was $52.6B or $88.79 per share representing a 31% control premium.
B5: Goodwill and intangible assets acquired were valued at $78.8B including $65.1B created via this transaction.
B7: The transaction was expected to result in 51%/49% ownership of Kraft Heinz in favor of the Heinz shareholders.
B8: Based on the valuation of Kraft, the new company (Kraft Heinz) was valued at $87.5 billion and Heinz was valued at $44.6B.
B10: Combined | C10: Heinz | E10: Acquisition of
A11: FYE Near 12/31: | B11: 2015 | C11: 2014 | D11: Change | E11: Kraft | F11: (From acquisition footnote)
A12: Assets
A13: Cash and Equivalents | B13: 4837 | C13: 2298 | D13: =+B13-C13 -> 2539
A14: Trade receivables | B14: 871 | C14: 690 | D14: =+B14-C14 -> 181
A15: Inventories | B15: 2618 | C15: 1185 | D15: =+B15-C15 -> 1433
A16: Other current assets | B16: =+B17-SUM(B13:B15) -> 1454 | C16: =+C17-SUM(C13:C15) -> 742 | D16: =+B16-C16 -> 712
A17: Total current assets | B17: 9780 | C17: 4915 | D17: =+B17-C17 -> 4865 | E17: =314+3423 -> 3737
A18: PP&E - Net | B18: 6524 | C18: 2365 | D18: =+B18-C18 -> 4159 | E18: 4193
A19: Goodwill | B19: 43051 | C19: 14959 | D19: =+B19-C19 -> 28092 | E19: 29029
A20: Other intangibles | B20: 62120 | C20: 13188 | D20: =+B20-C20 -> 48932 | E20: 49749
A21: Other assets | B21: 1498 | C21: 1144 | D21: =+B21-C21 -> 354 | E21: 214
A22: Total assets | B22: =SUM(B17:B21) -> 122973 | C22: =SUM(C17:C21) -> 36571 | D22: =SUM(D17:D21) -> 86402 | E22: =SUM(E17:E21) -> 86922
A23: Liabilities and Equity:
A24: Accounts payable | B24: 2844 | C24: 1651 | D24: =+B24-C24 -> 1193
A25: Other current liabilities | B25: =+B26-B24 -> 4088 | C25: =+C26-C24 -> 1441 | D25: =+D26-D24 -> 2647
A26: Total current liabilities | B26: 6932 | C26: 3092 | D26: =+B26-C26 -> 3840 | E26: 3026
A27: Long-term debt | B27: 25151 | C27: 13358 | D27: =+B27-C27 -> 11793 | E27: 9286
A28: Other liabilities | B28: =+B29-SUM(B26:B27) -> 24677 | C28: =+C29-SUM(C26:C27) -> 4465 | D28: =+B28-C28 -> 20212 | E28: =4734+17239 -> 21973
A29: Total liabilities and redeemable NCI) | B29: =56737+23 -> 56760 | C29: =20886+29 -> 20915 | D29: =+B29-C29 -> 35845 | E29: =SUM(E26:E28) -> 34285
A30: Preferred stock | B30: 8320 | C30: 8320 | D30: =+B30-C30 -> 0
A31: Common Equity | B31: 57893 | C31: 7336 | D31: =+B31-C31 -> 50557 | E31: =+E22-E29 -> 52637
A32: Total liabilities and equity | B32: =SUM(B29:B31) -> 122973 | C32: =SUM(C29:C31) -> 36571 | D32: =SUM(D29:D31) -> 86402 | E32: =SUM(E29:E31) -> 86922
B33: =+B32-B22 -> 0 | C33: =+C32-C22 -> 0 | D33: =+D32-D22 -> 0 | E33: =+E32-E22 -> 0
A34: Net Cash used in acquisition | E34: 9468
A35: Cash acquired | E35: 314
A36: Special cash dividend paid ($16.50 per share) | E36: =SUM(E34:E35) -> 9782 | F36: =+E36/16.5 -> 592.84848 | G36: Shares
A37: Equity Issued at fair value | E37: 42855 | F37: =+E37/F36 -> 72.286598 | G37: Price per share
A38: Total consideration | E38: =SUM(E36:E37) -> 52637 | F38: =+E38/F36 -> 88.786598 | G38: Including special dividend
F39: 61.33 | G39: Kraft stock price immediately prior to merger announcemt
F40: =(+F38-F39)/F38 -> 0.30924259 | G40: Control Premium to Kraft shareholders.
A42: Kraft Foods
A43: Last Balance Sheet compared to Valuation
A44: =+A3 -> In millions except per share data
...

Sheet As Reported
A1: Kraft Heinz Company | B1: As reported | K1: =+B1 -> As reported | R1: =+B1 -> As reported
A2: Consolidated Balance Sheets | K2: Common Size on Total Assets | R2: Horizontal(Growth) Analysis
A3: in millions except per share data | F3: Late Filing | G3: Restated | P3: Restated | R3: 5 Year | S3: Annual | T3: 2021 to | U3: 2020 to | V3: 2019 to | W3: 2018 to | X3: 2017 to
A4: Fiscal year ended 12/31 | B4: 2022 | C4: 2021 | D4: 2020 | E4: 2019 | F4: 2018 | G4: 2017 | H4: 2016 | I4: 2015 | K4: 2022 | L4: 2021 | M4: 2020 | N4: 2019 | O4: 2018 | P4: 2017 | R4: CAGR | S4: Average | T4: 2022 | U4: 2021 | V4: 2020 | W4: 2019 | X4: 2018
A5: Assets:
A6: Cash and equivalents | B6: 1040 | C6: 3445 | D6: 3417 | E6: 2279 | F6: 1130 | G6: 1629 | K6: =+B6/B$18 -> 0.011490062 | L6: =+C6/C$18 -> 0.036886738 | M6: =+D6/D$18 -> 0.034228188 | N6: =+E6/E$18 -> 0.022464268 | O6: =+F6/F$18 -> 0.01092199 | P6: =+G6/G$18 -> 0.0135646 | R6: =RATE(5,0,-G6,B6) -> -0.085839502 | S6: =AVERAGE(T6:X6) -> 0.10398284 | T6: =(+B6-C6)/C6 -> -0.69811321 | U6: =(+C6-D6)/D6 -> 0.0081943225 | V6: =(+D6-E6)/E6 -> 0.49934182 | W6: =(+E6-F6)/F6 -> 1.0168142 | X6: =(+F6-G6)/G6 -> -0.3063229
A7: Trade receivables | B7: 2120 | C7: 1957 | D7: 2063 | E7: 1973 | F7: 2129 | G7: 921 | K7: =+B7/B$18 -> 0.02342205 | L7: =+C7/C$18 -> 0.020954237 | M7: =+D7/D$18 -> 0.020665131 | N7: =+E7/E$18 -> 0.019448004 | O7: =+F7/F$18 -> 0.020577802 | P7: =+G7/G$18 -> 0.0076691203 | R7: =RATE(5,0,-G7,B7) -> 0.18144973 | S7: =AVERAGE(T7:X7) -> 0.26317381 | T7: =(+B7-C7)/C7 -> 0.083290751 | U7: =(+C7-D7)/D7 -> -0.051381483 | V7: =(+D7-E7)/E7 -> 0.045615813 | W7: =(+E7-F7)/F7 -> -0.073273837 | X7: =(+F7-G7)/G7 -> 1.3116178
A8: Income tax receivable | B8: 0 | C8: 0 | D8: 0 | E8: 0 | F8: 152 | G8: 538 | K8: =+B8/B$18 -> 0 | L8: =+C8/C$18 -> 0 | M8: =+D8/D$18 -> 0 | N8: =+E8/E$18 -> 0 | O8: =+F8/F$18 -> 0.0014691526 | P8: =+G8/G$18 -> 0.0044798987 | R8: =RATE(5,0,-G8,B8) -> -0.99999941 | S8: =AVERAGE(T8:X8) -> -0.85873606 | W8: =(+E8-F8)/F8 -> -1 | X8: =(+F8-G8)/G8 -> -0.71747212
A9: Inventories | B9: 3651 | C9: 2729 | D9: 2554 | E9: 2721 | F9: 2667 | G9: 2760 | K9: =+B9/B$18 -> 0.040336747 | L9: =+C9/C$18 -> 0.029220293 | M9: =+D9/D$18 -> 0.025583492 | N9: =+E9/E$18 -> 0.026821094 | O9: =+F9/F$18 -> 0.025777829 | P9: =+G9/G$18 -> 0.02298238 | R9: =RATE(5,0,-G9,B9) -> 0.057549125 | S9: =AVERAGE(T9:X9) -> 0.066309997 | T9: =(+B9-C9)/C9 -> 0.33785269 | U9: =(+C9-D9)/D9 -> 0.068519969 | V9: =(+D9-E9)/E9 -> -0.061374495 | W9: =(+E9-F9)/F9 -> 0.020247469 | X9: =(+F9-G9)/G9 -> -0.033695652
A10: Prepaid expenses | B10: 240 | C10: 136 | D10: 351 | E10: 384 | F10: 400 | G10: 345 | K10: =+B10/B$18 -> 0.0026515528 | L10: =+C10/C$18 -> 0.0014561963 | M10: =+D10/D$18 -> 0.0035159772 | N10: =+E10/E$18 -> 0.0037851158 | O10: =+F10/F$18 -> 0.0038661911 | P10: =+G10/G$18 -> 0.0028727975 | R10: =RATE(5,0,-G10,B10) -> -0.070009677 | S10: =AVERAGE(T10:X10) -> 0.037130612 | T10: =(+B10-C10)/C10 -> 0.76470588 | U10: =(+C10-D10)/D10 -> -0.61253561 | V10: =(+D10-E10)/E10 -> -0.0859375 | W10: =(+E10-F10)/F10 -> -0.04 | X10: =(+F10-G10)/G10 -> 0.15942029
A11: Other current assets | B11: 842 | C11: 716 | D11: 574 | E11: 618 | F11: 1221 | G11: 655 | K11: =+B11/B$18 -> 0.0093025311 | L11: =+C11/C$18 -> 0.0076664454 | M11: =+D11/D$18 -> 0.0057497746 | N11: =+E11/E$18 -> 0.0060916708 | O11: =+F11/F$18 -> 0.011801548 | P11: =+G11/G$18 -> 0.0054541518 | R11: =RATE(5,0,-G11,B11) -> 0.051511818 | S11: =AVERAGE(T11:X11) -> 0.14448633 | T11: =(+B11-C11)/C11 -> 0.17597765 | U11: =(+C11-D11)/D11 -> 0.24738676 | V11: =(+D11-E11)/E11 -> -0.071197411 | W11: =(+E11-F11)/F11 -> -0.49385749 | X11: =(+F11-G11)/G11 -> 0.86412214
A12: Assets held for sale | B12: 4 | C12: 11 | D12: 1863 | E12: 122 | F12: 1376 | G12: 353 | K12: =+B12/B$18 -> 4.4192547e-05 | L12: =+C12/C$18 -> 0.00011778059 | M12: =+D12/D$18 -> 0.018661725 | N12: =+E12/E$18 -> 0.0012025628 | O12: =+F12/F$18 -> 0.013299697 | P12: =+G12/G$18 -> 0.0029394131 | R12: =RATE(5,0,-G12,B12) -> -0.59181498 | S12: =AVERAGE(T12:X12) -> 2.9253425 | T12: =(+B12-C12)/C12 -> -0.63636364 | U12: =(+C12-D12)/D12 -> -0.99409554 | V12: =(+D12-E12)/E12 -> 14.270492 | W12: =(+E12-F12)/F12 -> -0.91133721 | X12: =(+F12-G12)/G12 -> 2.898017
A13: Total current assets | B13: =SUM(B6:B12) -> 7897 | C13: =SUM(C6:C12) -> 8994 | D13: =SUM(D6:D12) -> 10822 | E13: =SUM(E6:E12) -> 8097 | F13: =SUM(F6:F12) -> 9075 | G13: =SUM(G6:G12) -> 7201 | H13: 8753 | I13: 9780 | K13: =+B13/B$18 -> 0.087247136 | L13: =+C13/C$18 -> 0.09630169 | M13: =+D13/D$18 -> 0.10840429 | N13: =+E13/E$18 -> 0.079812716 | O13: =+F13/F$18 -> 0.087714211 | P13: =+G13/G$18 -> 0.059962362 | R13: =RATE(5,0,-G13,B13) -> 0.018623908 | S13: =AVERAGE(T13:X13) -> 0.039626412 | T13: =(+B13-C13)/C13 -> -0.1219702 | U13: =(+C13-D13)/D13 -> -0.16891517 | V13: =(+D13-E13)/E13 -> 0.3365444 | W13: =(+E13-F13)/F13 -> -0.1077686 | X13: =(+F13-G13)/G13 -> 0.26024163
A14: Property, plant & equipment - net | B14: 6740 | C14: 6806 | D14: 6876 | E14: 7055 | F14: 7078 | G14: 7061 | H14: 6688 | I14: 6524 | K14: =+B14/B$18 -> 0.074464442 | L14: =+C14/C$18 -> 0.07287406 | M14: =+D14/D$18 -> 0.068877091 | N14: =+E14/E$18 -> 0.069541646 | O14: =+F14/F$18 -> 0.068412252 | P14: =+G14/G$18 -> 0.058796589 | R14: =RATE(5,0,-G14,B14) -> -0.0092621911 | S14: =AVERAGE(T14:X14) -> -0.0092183309 | T14: =(+B14-C14)/C14 -> -0.0096973259 | U14: =(+C14-D14)/D14 -> -0.010180337 | V14: =(+D14-E14)/E14 -> -0.025372077 | W14: =(+E14-F14)/F14 -> -0.0032495055 | X14: =(+F14-G14)/G14 -> 0.002407591
A15: Goodwill | B15: 30833 | C15: 31296 | D15: 33089 | E15: 35546 | F15: 36503 | G15: 44825 | H15: 44125 | I15: 43051 | K15: =+B15/B$18 -> 0.3406472 | L15: =+C15/C$18 -> 0.33509647 | M15: =+D15/D$18 -> 0.33145347 | N15: =+E15/E$18 -> 0.3503795 | O15: =+F15/F$18 -> 0.35281894 | P15: =+G15/G$18 -> 0.3732555 | R15: =RATE(5,0,-G15,B15) -> -0.072104439 | S15: =AVERAGE(T15:X15) -> -0.069995093 | T15: =(+B15-C15)/C15 -> -0.014794223 | U15: =(+C15-D15)/D15 -> -0.054187192 | V15: =(+D15-E15)/E15 -> -0.069121701 | W15: =(+E15-F15)/F15 -> -0.026217023 | X15: =(+F15-G15)/G15 -> -0.18565533
A16: Intangible assets | B16: 42649 | C16: 43542 | D16: 46667 | E16: 48652 | F16: 49468 | G16: 59432 | H16: 59297 | I16: 62120 | K16: =+B16/B$18 -> 0.47119198 | L16: =+C16/C$18 -> 0.46621839 | M16: =+D16/D$18 -> 0.46746469 | N16: =+E16/E$18 -> 0.47956629 | O16: =+F16/F$18 -> 0.47813186 | P16: =+G16/G$18 -> 0.49488725 | R16: =RATE(5,0,-G16,B16) -> -0.064211505 | S16: =AVERAGE(T16:X16) -> -0.062484402 | T16: =(+B16-C16)/C16 -> -0.020508934 | U16: =(+C16-D16)/D16 -> -0.066963807 | V16: =(+D16-E16)/E16 -> -0.040799967 | W16: =(+E16-F16)/F16 -> -0.016495512 | X16: =(+F16-G16)/G16 -> -0.16765379
A17: Other assets | B17: 2394 | C17: 2756 | D17: 2376 | E17: 2100 | F17: 1337 | G17: 1573 | H17: 1617 | I17: 1498 | K17: =+B17/B$18 -> 0.026449239 | L17: =+C17/C$18 -> 0.02950939 | M17: =+D17/D$18 -> 0.023800461 | N17: =+E17/E$18 -> 0.020699852 | O17: =+F17/F$18 -> 0.012922744 | P17: =+G17/G$18 -> 0.013098291 | R17: =RATE(5,0,-G17,B17) -> 0.087624757 | S17: =AVERAGE(T17:X17) -> 0.11613206 | T17: =(+B17-C17)/C17 -> -0.13134978 | U17: =(+C17-D17)/D17 -> 0.15993266 | V17: =(+D17-E17)/E17 -> 0.13142857 | W17: =(+E17-F17)/F17 -> 0.57068063 | X17: =(+F17-G17)/G17 -> -0.15003179
A18: Total Assets | B18: =SUM(B13:B17) -> 90513 | C18: =SUM(C13:C17) -> 93394 | D18: =SUM(D13:D17) -> 99830 | E18: =SUM(E13:E17) -> 101450 | F18: =SUM(F13:F17) -> 103461 | G18: =SUM(G13:G17) -> 120092 | H18: =SUM(H13:H17) -> 120480 | I18: =SUM(I13:I17) -> 122973 | K18: =+B18/B$18 -> 1 | L18: =+C18/C$18 -> 1 | M18: =+D18/D$18 -> 1 | N18: =+E18/E$18 -> 1 | O18: =+F18/F$18 -> 1 | P18: =+G18/G$18 -> 1 | R18: =RATE(5,0,-G18,B18) -> -0.054983533 | S18: =AVERAGE(T18:X18) -> -0.053841726 | T18: =(+B18-C18)/C18 -> -0.030847806 | U18: =(+C18-D18)/D18 -> -0.064469598 | V18: =(+D18-E18)/E18 -> -0.015968457 | W18: =(+E18-F18)/F18 -> -0.019437276 | X18: =(+F18-G18)/G18 -> -0.13848549
A19: Liabilities and Equity
A20: Short-term Debt | B20: 6 | C20: 14 | D20: 6 | E20: 6 | F20: 21 | G20: 462 | K20: =+B20/B$18 -> 6.628882e-05 | L20: =+C20/C$18 -> 0.00014990256 | M20: =+D20/D$18 -> 6.0102174e-05 | N20: =+E20/E$18 -> 5.9142435e-05 | O20: =+F20/F$18 -> 0.00020297503 | P20: =+G20/G$18 -> 0.0038470506 | R20: =RATE(5,0,-G20,B20) -> -0.58052908 | S20: =AVERAGE(T20:X20) -> -0.18138528 | T20: =(+B20-C20)/C20 -> -0.57142857 | U20: =(+C20-D20)/D20 -> 1.3333333 | V20: =(+D20-E20)/E20 -> 0 | W20: =(+E20-F20)/F20 -> -0.71428571 | X20: =(+F20-G20)/G20 -> -0.95454545
A21: Current portion of LT Debt | B21: 831 | C21: 740 | D21: 230 | E21: 1022 | F21: 377 | G21: 2733 | K21: =+B21/B$18 -> 0.0091810016 | L21: =+C21/C$18 -> 0.0079234212 | M21: =+D21/D$18 -> 0.0023039167 | N21: =+E21/E$18 -> 0.010073928 | O21: =+F21/F$18 -> 0.0036438851 | P21: =+G21/G$18 -> 0.022757553 | R21: =RATE(5,0,-G21,B21) -> -0.21188013 | S21: =AVERAGE(T21:X21) -> 0.48284644 | T21: =(+B21-C21)/C21 -> 0.12297297 | U21: =(+C21-D21)/D21 -> 2.2173913 | V21: =(+D21-E21)/E21 -> -0.77495108 | W21: =(+E21-F21)/F21 -> 1.7108753 | X21: =(+F21-G21)/G21 -> -0.86205635
A22: Trade payables | B22: 4848 | C22: 4753 | D22: 4304 | E22: 4003 | F22: 4153 | G22: 4362 | K22: =+B22/B$18 -> 0.053561367 | L22: =+C22/C$18 -> 0.05089192 | M22: =+D22/D$18 -> 0.043113293 | N22: =+E22/E$18 -> 0.039457861 | O22: =+F22/F$18 -> 0.040140729 | P22: =+G22/G$18 -> 0.036322153 | R22: =RATE(5,0,-G22,B22) -> 0.021351874 | S22: =AVERAGE(T22:X22) -> 0.023094055 | T22: =(+B22-C22)/C22 -> 0.019987376 | U22: =(+C22-D22)/D22 -> 0.10432156 | V22: =(+D22-E22)/E22 -> 0.075193605 | W22: =(+E22-F22)/F22 -> -0.036118469 | X22: =(+F22-G22)/G22 -> -0.047913801
A23: Accrued marketing | B23: 749 | C23: 804 | D23: 946 | E23: 647 | F23: 722 | G23: 689 | K23: =+B23/B$18 -> 0.0082750544 | L23: =+C23/C$18 -> 0.0086086901 | M23: =+D23/D$18 -> 0.0094761094 | N23: =+E23/E$18 -> 0.0063775259 | O23: =+F23/F$18 -> 0.006978475 | P23: =+G23/G$18 -> 0.0057372681 | R23: =RATE(5,0,-G23,B23) -> 0.016839759 | S23: =AVERAGE(T23:X23) -> 0.037527327 | T23: =(+B23-C23)/C23 -> -0.06840796 | U23: =(+C23-D23)/D23 -> -0.15010571 | V23: =(+D23-E23)/E23 -> 0.46213292 | W23: =(+E23-F23)/F23 -> -0.10387812 | X23: =(+F23-G23)/G23 -> 0.047895501
A24: Interest payable | B24: 264 | C24: 268 | D24: 358 | E24: 384 | F24: 408 | G24: 419 | K24: =+B24/B$18 -> 0.0029167081 | L24: =+C24/C$18 -> 0.0028695634 | M24: =+D24/D$18 -> 0.0035860964 | N24: =+E24/E$18 -> 0.0037851158 | O24: =+F24/F$18 -> 0.0039435149 | P24: =+G24/G$18 -> 0.0034889918 | R24: =RATE(5,0,-G24,B24) -> -0.088245363 | S24: =AVERAGE(T24:X24) -> -0.083821373 | T24: =(+B24-C24)/C24 -> -0.014925373 | U24: =(+C24-D24)/D24 -> -0.25139665 | V24: =(+D24-E24)/E24 -> -0.067708333 | W24: =(+E24-F24)/F24 -> -0.058823529 | X24: =(+F24-G24)/G24 -> -0.026252983
A25: Income tax payable | B25: 136 | C25: 541 | D25: 0 | E25: 0 | F25: 0 | G25: 0 | K25: =+B25/B$18 -> 0.0015025466 | L25: =+C25/C$18 -> 0.0057926633 | M25: =+D25/D$18 -> 0 | N25: =+E25/E$18 -> 0 | O25: =+F25/F$18 -> 0 | P25: =+G25/G$18 -> 0 | S25: =AVERAGE(T25:X25) -> -0.74861368 | T25: =(+B25-C25)/C25 -> -0.74861368
A26: Liabilities held for sale | B26: 0 | C26: 0 | D26: 17 | E26: 9 | F26: 55 | G26: 0 | K26: =+B26/B$18 -> 0 | L26: =+C26/C$18 -> 0 | M26: =+D26/D$18 -> 0.00017028949 | N26: =+E26/E$18 -> 8.8713652e-05 | O26: =+F26/F$18 -> 0.00053160128 | P26: =+G26/G$18 -> 0 | S26: =AVERAGE(T26:X26) -> -0.31582492 | U26: =(+C26-D26)/D26 -> -1 | V26: =(+D26-E26)/E26 -> 0.88888889 | W26: =(+E26-F26)/F26 -> -0.83636364
A27: Other current liabilities | B27: 2194 | C27: 1944 | D27: 2200 | E27: 1804 | F27: 1767 | G27: 1489 | K27: =+B27/B$18 -> 0.024239612 | L27: =+C27/C$18 -> 0.020815042 | M27: =+D27/D$18 -> 0.022037464 | N27: =+E27/E$18 -> 0.017782159 | O27: =+F27/F$18 -> 0.017078899 | P27: =+G27/G$18 -> 0.012398828 | R27: =RATE(5,0,-G27,B27) -> 0.080608514 | S27: =AVERAGE(T27:X27) -> 0.087878262 | T27: =(+B27-C27)/C27 -> 0.12860082 | U27: =(+C27-D27)/D27 -> -0.11636364 | V27: =(+D27-E27)/E27 -> 0.2195122 | W27: =(+E27-F27)/F27 -> 0.020939445 | X27: =(+F27-G27)/G27 -> 0.18670248
A28: Total current liabilities | B28: =SUM(B20:B27) -> 9028 | C28: =SUM(C20:C27) -> 9064 | D28: =SUM(D20:D27) -> 8061 | E28: =SUM(E20:E27) -> 7875 | F28: =SUM(F20:F27) -> 7503 | G28: =SUM(G20:G27) -> 10154 | H28: 9501 | I28: 6932 | K28: =+B28/B$18 -> 0.099742578 | L28: =+C28/C$18 -> 0.097051202 | M28: =+D28/D$18 -> 0.08074727 | N28: =+E28/E$18 -> 0.077624446 | O28: =+F28/F$18 -> 0.07252008 | P28: =+G28/G$18 -> 0.084551844 | R28: =RATE(5,0,-G28,B28) -> -0.023233226 | S28: =AVERAGE(T28:X28) -> -0.013485134 | T28: =(+B28-C28)/C28 -> -0.0039717564 | U28: =(+C28-D28)/D28 -> 0.12442625 | V28: =(+D28-E28)/E28 -> 0.023619048 | W28: =(+E28-F28)/F28 -> 0.049580168 | X28: =(+F28-G28)/G28 -> -0.26107938
A29: Long-term debt | B29: 19233 | C29: 21061 | D29: 28070 | E29: 28216 | F29: 30770 | G29: 28308 | H29: 29713 | I29: 25151 | K29: =+B29/B$18 -> 0.21248881 | L29: =+C29/C$18 -> 0.22550699 | M29: =+D29/D$18 -> 0.281178 | N29: =+E29/E$18 -> 0.27812716 | O29: =+F29/F$18 -> 0.29740675 | P29: =+G29/G$18 -> 0.23571928 | R29: =RATE(5,0,-G29,B29) -> -0.074391 | S29: =AVERAGE(T29:X29) -> -0.06753962 | T29: =(+B29-C29)/C29 -> -0.086795499 | U29: =(+C29-D29)/D29 -> -0.24969719 | V29: =(+D29-E29)/E29 -> -0.0051743692 | W29: =(+E29-F29)/F29 -> -0.083002925 | X29: =(+F29-G29)/G29 -> 0.086971881
A30: Deferred income taxes | B30: 10152 | C30: 10536 | D30: 11462 | E30: 11878 | F30: 12202 | G30: 14039 | H30: 20848 | I30: 21497 | K30: =+B30/B$18 -> 0.11216068 | L30: =+C30/C$18 -> 0.11281239 | M30: =+D30/D$18 -> 0.11481519 | N30: =+E30/E$18 -> 0.11708231 | O30: =+F30/F$18 -> 0.11793816 | P30: =+G30/G$18 -> 0.11690204 | R30: =RATE(5,0,-G30,B30) -> -0.062776678 | S30: =AVERAGE(T30:X30) -> -0.061932139 | T30: =(+B30-C30)/C30 -> -0.036446469 | U30: =(+C30-D30)/D30 -> -0.080788693 | V30: =(+D30-E30)/E30 -> -0.035022731 | W30: =(+E30-F30)/F30 -> -0.026553024 | X30: =(+F30-G30)/G30 -> -0.13084978
A31: Accrued PRB costs | B31: 144 | C31: 205 | D31: 243 | E31: 273 | F31: 306 | G31: 427 | H31: 2038 | I31: 2405 | K31: =+B31/B$18 -> 0.0015909317 | L31: =+C31/C$18 -> 0.0021950018 | M31: =+D31/D$18 -> 0.002434138 | N31: =+E31/E$18 -> 0.0026909808 | O31: =+F31/F$18 -> 0.0029576362 | P31: =+G31/G$18 -> 0.0035556074 | R31: =RATE(5,0,-G31,B31) -> -0.19538723 | S31: =AVERAGE(T31:X31) -> -0.19100904 | T31: =(+B31-C31)/C31 -> -0.29756098 | U31: =(+C31-D31)/D31 -> -0.1563786 | V31: =(+D31-E31)/E31 -> -0.10989011 | W31: =(+E31-F31)/F31 -> -0.10784314 | X31: =(+F31-G31)/G31 -> -0.28337237
A32: LT deferred income | B32: 1477 | C32: 1534 | D32: 0 | E32: 0 | F32: 0 | G32: 0 | H32: 0 | I32: 0 | K32: =+B32/B$18 -> 0.016318098 | L32: =+C32/C$18 -> 0.016425038 | M32: =+D32/D$18 -> 0 | N32: =+E32/E$18 -> 0 | O32: =+F32/F$18 -> 0 | P32: =+G32/G$18 -> 0 | S32: =AVERAGE(T32:X32) -> -0.037157757 | T32: =(+B32-C32)/C32 -> -0.037157757
A33: Other non-current liabilities | B33: 1609 | C33: 1542 | D33: 1751 | E33: 1459 | F33: 902 | G33: 1088 | H33: 806 | I33: 752 | K33: =+B33/B$18 -> 0.017776452 | L33: =+C33/C$18 -> 0.016510697 | M33: =+D33/D$18 -> 0.017539818 | N33: =+E33/E$18 -> 0.014381469 | O33: =+F33/F$18 -> 0.008718261 | P33: =+G33/G$18 -> 0.0090597209 | R33: =RATE(5,0,-G33,B33) -> 0.081397671 | S33: =AVERAGE(T33:X33) -> 0.11415751 | T33: =(+B33-C33)/C33 -> 0.043450065 | U33: =(+C33-D33)/D33 -> -0.11936037 | V33: =(+D33-E33)/E33 -> 0.20013708 | W33: =(+E33-F33)/F33 -> 0.61751663 | X33: =(+F33-G33)/G33 -> -0.17095588
A34: Total liabilities | B34: =SUM(B28:B33) -> 41643 | C34: =SUM(C28:C33) -> 43942 | D34: =SUM(D28:D33) -> 49587 | E34: =SUM(E28:E33) -> 49701 | F34: =SUM(F28:F33) -> 51683 | G34: =SUM(G28:G33) -> 54016 | H34: =SUM(H28:H33) -> 62906 | I34: =SUM(I28:I33) -> 56737 | K34: =+B34/B$18 -> 0.46007756 | L34: =+C34/C$18 -> 0.47050132 | M34: =+D34/D$18 -> 0.49671441 | N34: =+E34/E$18 -> 0.48990636 | O34: =+F34/F$18 -> 0.49954089 | P34: =+G34/G$18 -> 0.4497885 | R34: =RATE(5,0,-G34,B34) -> -0.050699045 | S34: =AVERAGE(T34:X34) -> -0.049998615 | T34: =(+B34-C34)/C34 -> -0.052318966 | U34: =(+C34-D34)/D34 -> -0.11384032 | V34: =(+D34-E34)/E34 -> -0.0022937164 | W34: =(+E34-F34)/F34 -> -0.038349167 | X34: =(+F34-G34)/G34 -> -0.043190906
A35: Redeemable Non-controlling interest | B35: 40 | C35: 4 | D35: 0 | E35: 0 | F35: 3 | G35: 6 | H35: 0 | I35: 23 | K35: =+B35/B$18 -> 0.00044192547 | L35: =+C35/C$18 -> 4.2829304e-05 | M35: =+D35/D$18 -> 0 | N35: =+E35/E$18 -> 0 | O35: =+F35/F$18 -> 2.8996433e-05 | P35: =+G35/G$18 -> 4.9961696e-05 | R35: =RATE(5,0,-G35,B35) -> 0.46144255 | S35: =AVERAGE(T35:X35) -> 2.5 | T35: =(+B35-C35)/C35 -> 9 | W35: =(+E35-F35)/F35 -> -1 | X35: =(+F35-G35)/G35 -> -0.5
A36: Preferred stock - cumulative compounding | B36: 0 | C36: 0 | D36: 0 | E36: 0 | F36: 0 | G36: 0 | H36: 0 | I36: 8320 | K36: =+B36/B$18 -> 0 | L36: =+C36/C$18 -> 0 | M36: =+D36/D$18 -> 0 | N36: =+E36/E$18 -> 0 | O36: =+F36/F$18 -> 0 | P36: =+G36/G$18 -> 0
A37: Common stock | B37: 12 | C37: 12 | D37: 12 | E37: 12 | F37: 12 | G37: 12 | H37: 12 | I37: 12 | K37: =+B37/B$18 -> 0.00013257764 | L37: =+C37/C$18 -> 0.00012848791 | M37: =+D37/D$18 -> 0.00012020435 | N37: =+E37/E$18 -> 0.00011828487 | O37: =+F37/F$18 -> 0.00011598573 | P37: =+G37/G$18 -> 9.9923392e-05 | R37: =RATE(5,0,-G37,B37) -> 1.1505115e-16 | S37: =AVERAGE(T37:X37) -> 0 | T37: =(+B37-C37)/C37 -> 0 | U37: =(+C37-D37)/D37 -> 0 | V37: =(+D37-E37)/E37 -> 0 | W37: =(+E37-F37)/F37 -> 0 | X37: =(+F37-G37)/G37 -> 0
A38: Additional PIC | B38: 51834 | C38: 53379 | D38: 55096 | E38: 56828 | F38: 58723 | G38: 58634 | H38: 58593 | I38: 58375 | K38: =+B38/B$18 -> 0.57266912 | L38: =+C38/C$18 -> 0.57154635 | M38: =+D38/D$18 -> 0.55189823 | N38: =+E38/E$18 -> 0.56015771 | O38: =+F38/F$18 -> 0.56758585 | P38: =+G38/G$18 -> 0.48824235 | R38: =RATE(5,0,-G38,B38) -> -0.024352266 | S38: =AVERAGE(T38:X38) -> -0.024267589 | T38: =(+B38-C38)/C38 -> -0.028943967 | U38: =(+C38-D38)/D38 -> -0.031163787 | V38: =(+D38-E38)/E38 -> -0.030477933 | W38: =(+E38-F38)/F38 -> -0.03227015 | X38: =(+F38-G38)/G38 -> 0.0015178906
A39: Retained earnings (deficit) | B39: 489 | C39: -1682 | D39: -2694 | E39: -3060 | F39: -4853 | G39: 8495 | H39: 588 | I39: 0 | K39: =+B39/B$18 -> 0.0054025389 | L39: =+C39/C$18 -> -0.018009722 | M39: =+D39/D$18 -> -0.026985876 | N39: =+E39/E$18 -> -0.030162642 | O39: =+F39/F$18 -> -0.046906564 | P39: =+G39/G$18 -> 0.070737435 | R39: =RATE(5,0,-G39,B39) -> -0.43502518 | S39: =AVERAGE(T39:X39) -> -0.74534443 | T39: =(+B39-C39)/C39 -> -1.2907253 | U39: =(+C39-D39)/D39 -> -0.37564959 | V39: =(+D39-E39)/E39 -> -0.11960784 | W39: =(+E39-F39)/F39 -> -0.36946219 | X39: =(+F39-G39)/G39 -> -1.5712772
A40: Accum. OCI | B40: -2810 | C40: -1824 | D40: -1967 | E40: -1886 | F40: -1943 | G40: -1054 | H40: -1628 | I40: -671 | K40: =+B40/B$18 -> -0.031045264 | L40: =+C40/C$18 -> -0.019530163 | M40: =+D40/D$18 -> -0.019703496 | N40: =+E40/E$18 -> -0.018590439 | O40: =+F40/F$18 -> -0.018780023 | P40: =+G40/G$18 -> -0.0087766046 | R40: =RATE(5,0,-G40,B40) -> 0.21667096 | S40: =AVERAGE(T40:X40) -> 0.26498722 | T40: =(+B40-C40)/C40 -> 0.54057018 | U40: =(+C40-D40)/D40 -> -0.072699542 | V40: =(+D40-E40)/E40 -> 0.042948038 | W40: =(+E40-F40)/F40 -> -0.029336078 | X40: =(+F40-G40)/G40 -> 0.84345351
...

Sheet Reclassified
A1: Kraft Heinz Company | B1: Reclassified | J1: =+B1 -> Reclassified | R1: =+B1 -> Reclassified
A2: Consolidated Balance Sheets | J2: Common Size on Total Assets | R2: Horizontal(Growth) Analysis
A3: in millions except per share data | F3: Late filing | G3: Restated | O3: Restated | R3: 5 Year | S3: Annual | T3: 2021 to | U3: 2020 to | V3: 2019 to | W3: 2018 to | X3: 2017 to
A4: Fiscal Year ended 12/31: | B4: 2022 | C4: 2021 | D4: 2020 | E4: 2019 | F4: 2018 | G4: 2017 | J4: 2022 | K4: 2021 | L4: 2020 | M4: 2019 | N4: 2018 | O4: 2017 | R4: CAGR | S4: Average | T4: 2022 | U4: 2021 | V4: 2020 | W4: 2019 | X4: 2018
A5: Assets:
A6: Cash and equivalents | B6: 1040 | C6: 3445 | D6: 3417 | E6: 2279 | F6: 1130 | G6: 1629 | J6: =+B6/B$21 -> 0.011490062 | K6: =+C6/C$21 -> 0.036886738 | L6: =+D6/D$21 -> 0.034228188 | M6: =+E6/E$21 -> 0.022464268 | N6: =+F6/F$21 -> 0.01092199 | O6: =+G6/G$21 -> 0.0135646 | R6: =RATE(5,0,-G6,B6) -> -0.085839502 | S6: =AVERAGE(T6:X6) -> 0.10398284 | T6: =(+B6-C6)/C6 -> -0.69811321 | U6: =(+C6-D6)/D6 -> 0.0081943225 | V6: =(+D6-E6)/E6 -> 0.49934182 | W6: =(+E6-F6)/F6 -> 1.0168142 | X6: =(+F6-G6)/G6 -> -0.3063229
A7: Marketable Securities | B7: 0 | C7: 0 | D7: 0 | E7: 0 | F7: 0 | G7: 0
A8: Trade receivables | B8: 2120 | C8: 1957 | D8: 2063 | E8: 1973 | F8: 2129 | G8: 921 | J8: =+B8/B$21 -> 0.02342205 | K8: =+C8/C$21 -> 0.020954237 | L8: =+D8/D$21 -> 0.020665131 | M8: =+E8/E$21 -> 0.019448004 | N8: =+F8/F$21 -> 0.020577802 | O8: =+G8/G$21 -> 0.0076691203 | R8: =RATE(5,0,-G8,B8) -> 0.18144973 | S8: =AVERAGE(T8:X8) -> 0.26317381 | T8: =(+B8-C8)/C8 -> 0.083290751 | U8: =(+C8-D8)/D8 -> -0.051381483 | V8: =(+D8-E8)/E8 -> 0.045615813 | W8: =(+E8-F8)/F8 -> -0.073273837 | X8: =(+F8-G8)/G8 -> 1.3116178
A9: Inventories | B9: 3651 | C9: 2729 | D9: 2554 | E9: 2721 | F9: 2667 | G9: 2760 | J9: =+B9/B$21 -> 0.040336747 | K9: =+C9/C$21 -> 0.029220293 | L9: =+D9/D$21 -> 0.025583492 | M9: =+E9/E$21 -> 0.026821094 | N9: =+F9/F$21 -> 0.025777829 | O9: =+G9/G$21 -> 0.02298238 | R9: =RATE(5,0,-G9,B9) -> 0.057549125 | S9: =AVERAGE(T9:X9) -> 0.066309997 | T9: =(+B9-C9)/C9 -> 0.33785269 | U9: =(+C9-D9)/D9 -> 0.068519969 | V9: =(+D9-E9)/E9 -> -0.061374495 | W9: =(+E9-F9)/F9 -> 0.020247469 | X9: =(+F9-G9)/G9 -> -0.033695652
A10: Other current assets | B10: =+B192 -> 1086 | C10: =+C192 -> 863 | D10: =+D192 -> 2788 | E10: =+E192 -> 1124 | F10: =+F192 -> 3149 | G10: =+G192 -> 1891 | J10: =+B10/B$21 -> 0.011998276 | K10: =+C10/C$21 -> 0.0092404223 | L10: =+D10/D$21 -> 0.027927477 | M10: =+E10/E$21 -> 0.011079349 | N10: =+F10/F$21 -> 0.03043659 | O10: =+G10/G$21 -> 0.015746261 | R10: =RATE(5,0,-G10,B10) -> -0.10499047 | S10: =AVERAGE(T10:X10) -> 0.21411281 | T10: =(+B10-C10)/C10 -> 0.25840093 | U10: =(+C10-D10)/D10 -> -0.69045911 | V10: =(+D10-E10)/E10 -> 1.480427 | W10: =(+E10-F10)/F10 -> -0.64306129 | X10: =(+F10-G10)/G10 -> 0.66525648
A11: Total current assets | B11: =SUM(B6:B10) -> 7897 | C11: =SUM(C6:C10) -> 8994 | D11: =SUM(D6:D10) -> 10822 | E11: =SUM(E6:E10) -> 8097 | F11: =SUM(F6:F10) -> 9075 | G11: =SUM(G6:G10) -> 7201 | J11: =+B11/B$21 -> 0.087247136 | K11: =+C11/C$21 -> 0.09630169 | L11: =+D11/D$21 -> 0.10840429 | M11: =+E11/E$21 -> 0.079812716 | N11: =+F11/F$21 -> 0.087714211 | O11: =+G11/G$21 -> 0.059962362 | R11: =RATE(5,0,-G11,B11) -> 0.018623908 | S11: =AVERAGE(T11:X11) -> 0.039626412 | T11: =(+B11-C11)/C11 -> -0.1219702 | U11: =(+C11-D11)/D11 -> -0.16891517 | V11: =(+D11-E11)/E11 -> 0.3365444 | W11: =(+E11-F11)/F11 -> -0.1077686 | X11: =(+F11-G11)/G11 -> 0.26024163
A12: Land | B12: =+B170 -> 200 | C12: =+C170 -> 207 | D12: =+D170 -> 219 | E12: =+E170 -> 210 | F12: =+F170 -> 218 | G12: =+G170 -> 250 | J12: =+B12/B$21 -> 0.0022096273 | K12: =+C12/C$21 -> 0.0022164165 | L12: =+D12/D$21 -> 0.0021937293 | M12: =+E12/E$21 -> 0.0020699852 | N12: =+F12/F$21 -> 0.0021070742 | O12: =+G12/G$21 -> 0.0020817373 | R12: =RATE(5,0,-G12,B12) -> -0.0436475 | S12: =AVERAGE(T12:X12) -> -0.04209021 | T12: =(+B12-C12)/C12 -> -0.033816425 | U12: =(+C12-D12)/D12 -> -0.054794521 | V12: =(+D12-E12)/E12 -> 0.042857143 | W12: =(+E12-F12)/F12 -> -0.036697248 | X12: =(+F12-G12)/G12 -> -0.128
A13: Construction in progress | B13: =+B171 -> 1161 | C13: =+C171 -> 1002 | D13: =+D171 -> 792 | E13: =+E171 -> 1033 | F13: =+F171 -> 1165 | G13: =+G171 -> 1345 | J13: =+B13/B$21 -> 0.012826887 | K13: =+C13/C$21 -> 0.010728741 | L13: =+D13/D$21 -> 0.0079334869 | M13: =+E13/E$21 -> 0.010182356 | N13: =+F13/F$21 -> 0.011260282 | O13: =+G13/G$21 -> 0.011199747 | R13: =RATE(5,0,-G13,B13) -> -0.028993835 | S13: =AVERAGE(T13:X13) -> -0.011320126 | T13: =(+B13-C13)/C13 -> 0.15868263 | U13: =(+C13-D13)/D13 -> 0.26515152 | V13: =(+D13-E13)/E13 -> -0.23330106 | W13: =(+E13-F13)/F13 -> -0.11330472 | X13: =(+F13-G13)/G13 -> -0.133829
A14: Depreciable assets | B14: =+B172 -> 9591 | C14: =+C172 -> 9465 | D14: =+D172 -> 9428 | E14: =+E172 -> 8999 | F14: =+F172 -> 8279 | G14: =+G172 -> 7555 | J14: =+B14/B$21 -> 0.10596268 | K14: =+C14/C$21 -> 0.10134484 | L14: =+D14/D$21 -> 0.094440549 | M14: =+E14/E$21 -> 0.088703795 | N14: =+F14/F$21 -> 0.080020491 | O14: =+G14/G$21 -> 0.062910102 | R14: =RATE(5,0,-G14,B14) -> 0.048880193 | S14: =AVERAGE(T14:X14) -> 0.049541249 | T14: =(+B14-C14)/C14 -> 0.013312203 | U14: =(+C14-D14)/D14 -> 0.0039244803 | V14: =(+D14-E14)/E14 -> 0.047671964 | W14: =(+E14-F14)/F14 -> 0.086967025 | X14: =(+F14-G14)/G14 -> 0.095830576
A15: PP&E - at cost | B15: =+B173 -> 10952 | C15: =+C173 -> 10674 | D15: =+D173 -> 10439 | E15: =+E173 -> 10242 | F15: =+F173 -> 9662 | G15: =+G173 -> 9150 | J15: =+B15/B$21 -> 0.12099919 | K15: =+C15/C$21 -> 0.11429 | L15: =+D15/D$21 -> 0.10456777 | M15: =+E15/E$21 -> 0.10095614 | N15: =+F15/F$21 -> 0.093387847 | O15: =+G15/G$21 -> 0.076191586 | R15: =RATE(5,0,-G15,B15) -> 0.03660779 | S15: =AVERAGE(T15:X15) -> 0.036755223 | T15: =(+B15-C15)/C15 -> 0.026044594 | U15: =(+C15-D15)/D15 -> 0.022511735 | V15: =(+D15-E15)/E15 -> 0.019234525 | W15: =(+E15-F15)/F15 -> 0.06002898 | X15: =(+F15-G15)/G15 -> 0.055956284
A16: Accumulated depreciation | B16: =+B174 -> -4212 | C16: =+C174 -> -3868 | D16: =+D174 -> -3563 | E16: =+E174 -> -3187 | F16: =+F174 -> -2584 | G16: =+G174 -> -2089 | J16: =+B16/B$21 -> -0.046534752 | K16: =+C16/C$21 -> -0.041415937 | L16: =+D16/D$21 -> -0.035690674 | M16: =+E16/E$21 -> -0.03141449 | N16: =+F16/F$21 -> -0.024975595 | O16: =+G16/G$21 -> -0.017394997 | R16: =RATE(5,0,-G16,B16) -> 0.15056189 | S16: =AVERAGE(T16:X16) -> 0.15256616 | T16: =(+B16-C16)/C16 -> 0.08893485 | U16: =(+C16-D16)/D16 -> 0.085602021 | V16: =(+D16-E16)/E16 -> 0.11797929 | W16: =(+E16-F16)/F16 -> 0.23335913 | X16: =(+F16-G16)/G16 -> 0.23695548
A17: Property, plant & equipment - net | B17: 6740 | C17: 6806 | D17: 6876 | E17: 7055 | F17: 7078 | G17: 7061 | J17: =+B17/B$21 -> 0.074464442 | K17: =+C17/C$21 -> 0.07287406 | L17: =+D17/D$21 -> 0.068877091 | M17: =+E17/E$21 -> 0.069541646 | N17: =+F17/F$21 -> 0.068412252 | O17: =+G17/G$21 -> 0.058796589 | R17: =RATE(5,0,-G17,B17) -> -0.0092621911 | S17: =AVERAGE(T17:X17) -> -0.0092183309 | T17: =(+B17-C17)/C17 -> -0.0096973259 | U17: =(+C17-D17)/D17 -> -0.010180337 | V17: =(+D17-E17)/E17 -> -0.025372077 | W17: =(+E17-F17)/F17 -> -0.0032495055 | X17: =(+F17-G17)/G17 -> 0.002407591
A18: Right of Use assets | B18: =+B179 -> 668 | C18: =+C179 -> 569 | D18: =+D179 -> 562 | E18: =+E179 -> 542 | F18: =+F179 -> 0 | G18: =+G179 -> 0
A19: Goodwill and Intangibles (see detail) | B19: =+B196 -> 73482 | C19: =+C196 -> 74838 | D19: =+D196 -> 79756 | E19: =+E196 -> 84198 | F19: =+F196 -> 85971 | G19: =+G196 -> 104257 | J19: =+B19/B$21 -> 0.81183918 | K19: =+C19/C$21 -> 0.80131486 | L19: =+D19/D$21 -> 0.79891816 | M19: =+E19/E$21 -> 0.82994579 | N19: =+F19/F$21 -> 0.83095079 | O19: =+G19/G$21 -> 0.86814276 | R19: =RATE(5,0,-G19,B19) -> -0.067572339 | S19: =AVERAGE(T19:X19) -> -0.065711108 | T19: =(+B19-C19)/C19 -> -0.018119137 | U19: =(+C19-D19)/D19 -> -0.061663072 | V19: =(+D19-E19)/E19 -> -0.052756598 | W19: =(+E19-F19)/F19 -> -0.020623233 | X19: =(+F19-G19)/G19 -> -0.1753935
A20: Other assets | B20: =+B200 -> 1726 | C20: =+C200 -> 2187 | D20: =+D200 -> 1814 | E20: =+E200 -> 1558 | F20: =+F200 -> 1337 | G20: =+G200 -> 1573 | J20: =+B20/B$21 -> 0.019069084 | K20: =+C20/C$21 -> 0.023416922 | L20: =+D20/D$21 -> 0.018170891 | M20: =+E20/E$21 -> 0.015357319 | N20: =+F20/F$21 -> 0.012922744 | O20: =+G20/G$21 -> 0.013098291 | R20: =RATE(5,0,-G20,B20) -> 0.018737783 | S20: =AVERAGE(T20:X20) -> 0.034881754 | T20: =(+B20-C20)/C20 -> -0.21079104 | U20: =(+C20-D20)/D20 -> 0.20562293 | V20: =(+D20-E20)/E20 -> 0.16431322 | W20: =(+E20-F20)/F20 -> 0.16529544 | X20: =(+F20-G20)/G20 -> -0.15003179
A21: Total Assets | B21: =+B11+SUM(B17:B20) -> 90513 | C21: =+C11+SUM(C17:C20) -> 93394 | D21: =+D11+SUM(D17:D20) -> 99830 | E21: =+E11+SUM(E17:E20) -> 101450 | F21: =+F11+SUM(F17:F20) -> 103461 | G21: =+G11+SUM(G17:G20) -> 120092 | J21: =+B21/B$21 -> 1 | K21: =+C21/C$21 -> 1 | L21: =+D21/D$21 -> 1 | M21: =+E21/E$21 -> 1 | N21: =+F21/F$21 -> 1 | O21: =+G21/G$21 -> 1 | R21: =RATE(5,0,-G21,B21) -> -0.054983533 | S21: =AVERAGE(T21:X21) -> -0.053841726 | T21: =(+B21-C21)/C21 -> -0.030847806 | U21: =(+C21-D21)/D21 -> -0.064469598 | V21: =(+D21-E21)/E21 -> -0.015968457 | W21: =(+E21-F21)/F21 -> -0.019437276 | X21: =(+F21-G21)/G21 -> -0.13848549
A22: Liabilities and Equity
A23: Current Debt (see detail) | B23: =+B204 -> 837 | C23: =+C204 -> 754 | D23: =+D204 -> 236 | E23: =+E204 -> 1028 | F23: =+F204 -> 398 | G23: =+G204 -> 3195 | J23: =+B23/B$21 -> 0.0092472904 | K23: =+C23/C$21 -> 0.0080733238 | L23: =+D23/D$21 -> 0.0023640188 | M23: =+E23/E$21 -> 0.01013307 | N23: =+F23/F$21 -> 0.0038468602 | O23: =+G23/G$21 -> 0.026604603 | R23: =RATE(5,0,-G23,B23) -> -0.23501852 | S23: =AVERAGE(T23:X23) -> 0.44841021 | T23: =(+B23-C23)/C23 -> 0.11007958 | U23: =(+C23-D23)/D23 -> 2.1949153 | V23: =(+D23-E23)/E23 -> -0.77042802 | W23: =(+E23-F23)/F23 -> 1.5829146 | X23: =(+F23-G23)/G23 -> -0.87543036
A24: Trade payables | B24: 4848 | C24: 4753 | D24: 4304 | E24: 4003 | F24: 4153 | G24: 4362 | J24: =+B24/B$21 -> 0.053561367 | K24: =+C24/C$21 -> 0.05089192 | L24: =+D24/D$21 -> 0.043113293 | M24: =+E24/E$21 -> 0.039457861 | N24: =+F24/F$21 -> 0.040140729 | O24: =+G24/G$21 -> 0.036322153 | R24: =RATE(5,0,-G24,B24) -> 0.021351874 | S24: =AVERAGE(T24:X24) -> 0.023094055 | T24: =(+B24-C24)/C24 -> 0.019987376 | U24: =(+C24-D24)/D24 -> 0.10432156 | V24: =(+D24-E24)/E24 -> 0.075193605 | W24: =(+E24-F24)/F24 -> -0.036118469 | X24: =(+F24-G24)/G24 -> -0.047913801
A25: Deferred revenue | B25: 0 | C25: 0 | D25: 0 | E25: 0 | F25: 0 | G25: 0
A26: Current portion of operating lease liabilities | B26: =+B180 -> 125 | C26: =+C180 -> 133 | D26: =+D180 -> 135 | E26: =+E180 -> 147 | F26: =+F180 -> 0 | G26: =+G180 -> 0
A27: Other current liabilities (see detail) | B27: =+B212 -> 3218 | C27: =+C212 -> 3424 | D27: =+D212 -> 3386 | E27: =+E212 -> 2697 | F27: =+F212 -> 2952 | G27: =+G212 -> 2597 | J27: =+B27/B$21 -> 0.035552904 | K27: =+C27/C$21 -> 0.036661884 | L27: =+D27/D$21 -> 0.03391766 | M27: =+E27/E$21 -> 0.026584524 | N27: =+F27/F$21 -> 0.028532491 | O27: =+G27/G$21 -> 0.021625087 | R27: =RATE(5,0,-G27,B27) -> 0.04381328 | S27: =AVERAGE(T27:X27) -> 0.051368449 | T27: =(+B27-C27)/C27 -> -0.060163551 | U27: =(+C27-D27)/D27 -> 0.011222682 | V27: =(+D27-E27)/E27 -> 0.25546904 | W27: =(+E27-F27)/F27 -> -0.086382114 | X27: =(+F27-G27)/G27 -> 0.13669619
A28: Total current liabilities | B28: =SUM(B23:B27) -> 9028 | C28: =SUM(C23:C27) -> 9064 | D28: =SUM(D23:D27) -> 8061 | E28: =SUM(E23:E27) -> 7875 | F28: =SUM(F23:F27) -> 7503 | G28: =SUM(G23:G27) -> 10154 | J28: =+B28/B$21 -> 0.099742578 | K28: =+C28/C$21 -> 0.097051202 | L28: =+D28/D$21 -> 0.08074727 | M28: =+E28/E$21 -> 0.077624446 | N28: =+F28/F$21 -> 0.07252008 | O28: =+G28/G$21 -> 0.084551844 | R28: =RATE(5,0,-G28,B28) -> -0.023233226 | S28: =AVERAGE(T28:X28) -> -0.013485134 | T28: =(+B28-C28)/C28 -> -0.0039717564 | U28: =(+C28-D28)/D28 -> 0.12442625 | V28: =(+D28-E28)/E28 -> 0.023619048 | W28: =(+E28-F28)/F28 -> 0.049580168 | X28: =(+F28-G28)/G28 -> -0.26107938
A29: Long-term debt | B29: 19233 | C29: 21061 | D29: 28070 | E29: 28216 | F29: 30770 | G29: 28308 | J29: =+B29/B$21 -> 0.21248881 | K29: =+C29/C$21 -> 0.22550699 | L29: =+D29/D$21 -> 0.281178 | M29: =+E29/E$21 -> 0.27812716 | N29: =+F29/F$21 -> 0.29740675 | O29: =+G29/G$21 -> 0.23571928 | R29: =RATE(5,0,-G29,B29) -> -0.074391 | S29: =AVERAGE(T29:X29) -> -0.06753962 | T29: =(+B29-C29)/C29 -> -0.086795499 | U29: =(+C29-D29)/D29 -> -0.24969719 | V29: =(+D29-E29)/E29 -> -0.0051743692 | W29: =(+E29-F29)/F29 -> -0.083002925 | X29: =(+F29-G29)/G29 -> 0.086971881
A30: LT operating lease liabilities | B30: =+B181 -> 585 | C30: =+C181 -> 484 | D30: =+D181 -> 475 | E30: =+E181 -> 454 | F30: =+F181 -> 0 | G30: =+G181 -> 0
A31: Other non-current liabilities (see detail) | B31: =+B219 -> 12797 | C31: =+C219 -> 13333 | D31: =+D219 -> 12981 | E31: =+E219 -> 13156 | F31: =+F219 -> 13410 | G31: =+G219 -> 15554 | J31: =+B31/B$21 -> 0.14138301 | K31: =+C31/C$21 -> 0.14276078 | L31: =+D31/D$21 -> 0.13003105 | M31: =+E31/E$21 -> 0.12967965 | N31: =+F31/F$21 -> 0.12961406 | O31: =+G31/G$21 -> 0.12951737 | R31: =RATE(5,0,-G31,B31) -> -0.038269886 | S31: =AVERAGE(T31:X31) -> -0.036633962 | T31: =(+B31-C31)/C31 -> -0.040201005 | U31: =(+C31-D31)/D31 -> 0.027116555 | V31: =(+D31-E31)/E31 -> -0.013301915 | W31: =(+E31-F31)/F31 -> -0.018941089 | X31: =(+F31-G31)/G31 -> -0.13784236
A32: Total liabilities | B32: =SUM(B28:B31) -> 41643 | C32: =SUM(C28:C31) -> 43942 | D32: =SUM(D28:D31) -> 49587 | E32: =SUM(E28:E31) -> 49701 | F32: =SUM(F28:F31) -> 51683 | G32: =SUM(G28:G31) -> 54016 | J32: =+B32/B$21 -> 0.46007756 | K32: =+C32/C$21 -> 0.47050132 | L32: =+D32/D$21 -> 0.49671441 | M32: =+E32/E$21 -> 0.48990636 | N32: =+F32/F$21 -> 0.49954089 | O32: =+G32/G$21 -> 0.4497885 | R32: =RATE(5,0,-G32,B32) -> -0.050699045 | S32: =AVERAGE(T32:X32) -> -0.049998615 | T32: =(+B32-C32)/C32 -> -0.052318966 | U32: =(+C32-D32)/D32 -> -0.11384032 | V32: =(+D32-E32)/E32 -> -0.0022937164 | W32: =(+E32-F32)/F32 -> -0.038349167 | X32: =(+F32-G32)/G32 -> -0.043190906
A33: Redeemable Non-controlling interest | B33: 40 | C33: 4 | D33: 0 | E33: 0 | F33: 3 | G33: 6 | J33: =+B33/B$21 -> 0.00044192547 | K33: =+C33/C$21 -> 4.2829304e-05 | L33: =+D33/D$21 -> 0 | M33: =+E33/E$21 -> 0 | N33: =+F33/F$21 -> 2.8996433e-05 | O33: =+G33/G$21 -> 4.9961696e-05 | R33: =RATE(5,0,-G33,B33) -> 0.46144255 | S33: =AVERAGE(T33:X33) -> 2.5 | T33: =(+B33-C33)/C33 -> 9 | W33: =(+E33-F33)/F33 -> -1 | X33: =(+F33-G33)/G33 -> -0.5
A34: Total Equity | B34: =+B227 -> 48830 | C34: =+C227 -> 49448 | D34: =+D227 -> 50243 | E34: =+E227 -> 51749 | F34: =+F227 -> 51775 | G34: =+G227 -> 66070 | J34: =+B34/B$21 -> 0.53948052 | K34: =+C34/C$21 -> 0.52945585 | L34: =+D34/D$21 -> 0.50328559 | M34: =+E34/E$21 -> 0.51009364 | N34: =+F34/F$21 -> 0.50043011 | O34: =+G34/G$21 -> 0.55016154 | R34: =RATE(5,0,-G34,B34) -> -0.05868174 | S34: =AVERAGE(T34:X34) -> -0.054857339 | T34: =(+B34-C34)/C34 -> -0.012497978 | U34: =(+C34-D34)/D34 -> -0.0158231 | V34: =(+D34-E34)/E34 -> -0.029102012 | W34: =(+E34-F34)/F34 -> -0.00050217286 | X34: =(+F34-G34)/G34 -> -0.21636143
A35: Total Liabilities and Equity | B35: =+B34+B33+B32 -> 90513 | C35: =+C34+C33+C32 -> 93394 | D35: =+D34+D33+D32 -> 99830 | E35: =+E34+E33+E32 -> 101450 | F35: =+F34+F33+F32 -> 103461 | G35: =+G34+G33+G32 -> 120092 | J35: =+B35/B$21 -> 1 | K35: =+C35/C$21 -> 1 | L35: =+D35/D$21 -> 1 | M35: =+E35/E$21 -> 1 | N35: =+F35/F$21 -> 1 | O35: =+G35/G$21 -> 1 | R35: =RATE(5,0,-G35,B35) -> -0.054983533 | S35: =AVERAGE(T35:X35) -> -0.053841726 | T35: =(+B35-C35)/C35 -> -0.030847806 | U35: =(+C35-D35)/D35 -> -0.064469598 | V35: =(+D35-E35)/E35 -> -0.015968457 | W35: =(+E35-F35)/F35 -> -0.019437276 | X35: =(+F35-G35)/G35 -> -0.13848549
B36: =+B35-B21 -> 0 | C36: =+C35-C21 -> 0 | D36: =+D35-D21 -> 0 | E36: =+E35-E21 -> 0 | F36: =+F35-F21 -> 0 | G36: =+G35-G21 -> 0
A37: Shares issued | B37: 1243 | C37: 1235 | D37: 1228 | E37: 1224 | F37: 1224 | G37: 1221
A38: Treasury Shares | B38: -18 | C38: -11 | D38: -5 | E38: -3 | F38: -4 | G38: -2
A39: Shares Outstanding | B39: =+B37+B38 -> 1225 | C39: =+C37+C38 -> 1224 | D39: =+D37+D38 -> 1223 | E39: =+E37+E38 -> 1221 | F39: =+F37+F38 -> 1220 | G39: =+G37+G38 -> 1219
A40: Stock price at next 2/28 (60 days after FYE) | B40: 38.13 | C40: 39.22 | D40: 36.38 | E40: 24.77 | F40: 33.19 | G40: 67.14
...

Sheet Cash flow profile
A1: Kraft Heinz Company | B1: Reclassified | J1: =+B1 -> Reclassified | R1: =+B1 -> Reclassified
A2: Consolidated Balance Sheets | J2: Common Size on Total Assets | R2: Horizontal(Growth) Analysis
A3: in millions except per share data | F3: Late filing | G3: Restated | O3: Restated | R3: 5 Year | S3: Annual | T3: 2021 to | U3: 2020 to | V3: 2019 to | W3: 2018 to | X3: 2017 to
A4: Fiscal year ended 12/31: | B4: 2022 | C4: 2021 | D4: 2020 | E4: 2019 | F4: 2018 | G4: 2017 | J4: 2022 | K4: 2021 | L4: 2020 | M4: 2019 | N4: 2018 | O4: 2017 | R4: CAGR | S4: Average | T4: 2022 | U4: 2021 | V4: 2020 | W4: 2019 | X4: 2018
A5: Assets:
A6: Cash and equivalents | B6: 1040 | C6: 3445 | D6: 3417 | E6: 2279 | F6: 1130 | G6: 1629 | J6: =+B6/B$21 -> 0.011490062 | K6: =+C6/C$21 -> 0.036886738 | L6: =+D6/D$21 -> 0.034228188 | M6: =+E6/E$21 -> 0.022464268 | N6: =+F6/F$21 -> 0.01092199 | O6: =+G6/G$21 -> 0.0135646 | R6: =RATE(5,0,-G6,B6) -> -0.085839502 | S6: =AVERAGE(T6:X6) -> 0.10398284 | T6: =(+B6-C6)/C6 -> -0.69811321 | U6: =(+C6-D6)/D6 -> 0.0081943225 | V6: =(+D6-E6)/E6 -> 0.49934182 | W6: =(+E6-F6)/F6 -> 1.0168142 | X6: =(+F6-G6)/G6 -> -0.3063229
A7: Marketable Securities | B7: 0 | C7: 0 | D7: 0 | E7: 0 | F7: 0 | G7: 0
A8: Trade receivables | B8: 2120 | C8: 1957 | D8: 2063 | E8: 1973 | F8: 2129 | G8: 921 | J8: =+B8/B$21 -> 0.02342205 | K8: =+C8/C$21 -> 0.020954237 | L8: =+D8/D$21 -> 0.020665131 | M8: =+E8/E$21 -> 0.019448004 | N8: =+F8/F$21 -> 0.020577802 | O8: =+G8/G$21 -> 0.0076691203 | R8: =RATE(5,0,-G8,B8) -> 0.18144973 | S8: =AVERAGE(T8:X8) -> 0.26317381 | T8: =(+B8-C8)/C8 -> 0.083290751 | U8: =(+C8-D8)/D8 -> -0.051381483 | V8: =(+D8-E8)/E8 -> 0.045615813 | W8: =(+E8-F8)/F8 -> -0.073273837 | X8: =(+F8-G8)/G8 -> 1.3116178
A9: Inventories | B9: 3651 | C9: 2729 | D9: 2554 | E9: 2721 | F9: 2667 | G9: 2760 | J9: =+B9/B$21 -> 0.040336747 | K9: =+C9/C$21 -> 0.029220293 | L9: =+D9/D$21 -> 0.025583492 | M9: =+E9/E$21 -> 0.026821094 | N9: =+F9/F$21 -> 0.025777829 | O9: =+G9/G$21 -> 0.02298238 | R9: =RATE(5,0,-G9,B9) -> 0.057549125 | S9: =AVERAGE(T9:X9) -> 0.066309997 | T9: =(+B9-C9)/C9 -> 0.33785269 | U9: =(+C9-D9)/D9 -> 0.068519969 | V9: =(+D9-E9)/E9 -> -0.061374495 | W9: =(+E9-F9)/F9 -> 0.020247469 | X9: =(+F9-G9)/G9 -> -0.033695652
A10: Other current assets | B10: =+B240 -> 1086 | C10: =+C240 -> 863 | D10: =+D240 -> 2788 | E10: =+E240 -> 1124 | F10: =+F240 -> 3149 | G10: =+G240 -> 1891 | J10: =+B10/B$21 -> 0.011998276 | K10: =+C10/C$21 -> 0.0092404223 | L10: =+D10/D$21 -> 0.027927477 | M10: =+E10/E$21 -> 0.011079349 | N10: =+F10/F$21 -> 0.03043659 | O10: =+G10/G$21 -> 0.015746261 | R10: =RATE(5,0,-G10,B10) -> -0.10499047 | S10: =AVERAGE(T10:X10) -> 0.21411281 | T10: =(+B10-C10)/C10 -> 0.25840093 | U10: =(+C10-D10)/D10 -> -0.69045911 | V10: =(+D10-E10)/E10 -> 1.480427 | W10: =(+E10-F10)/F10 -> -0.64306129 | X10: =(+F10-G10)/G10 -> 0.66525648
A11: Total current assets | B11: =SUM(B6:B10) -> 7897 | C11: =SUM(C6:C10) -> 8994 | D11: =SUM(D6:D10) -> 10822 | E11: =SUM(E6:E10) -> 8097 | F11: =SUM(F6:F10) -> 9075 | G11: =SUM(G6:G10) -> 7201 | J11: =+B11/B$21 -> 0.087247136 | K11: =+C11/C$21 -> 0.09630169 | L11: =+D11/D$21 -> 0.10840429 | M11: =+E11/E$21 -> 0.079812716 | N11: =+F11/F$21 -> 0.087714211 | O11: =+G11/G$21 -> 0.059962362 | R11: =RATE(5,0,-G11,B11) -> 0.018623908 | S11: =AVERAGE(T11:X11) -> 0.039626412 | T11: =(+B11-C11)/C11 -> -0.1219702 | U11: =(+C11-D11)/D11 -> -0.16891517 | V11: =(+D11-E11)/E11 -> 0.3365444 | W11: =(+E11-F11)/F11 -> -0.1077686 | X11: =(+F11-G11)/G11 -> 0.26024163
A12: Land | B12: =+B218 -> 200 | C12: =+C218 -> 207 | D12: =+D218 -> 219 | E12: =+E218 -> 210 | F12: =+F218 -> 218 | G12: =+G218 -> 250 | J12: =+B12/B$21 -> 0.0022096273 | K12: =+C12/C$21 -> 0.0022164165 | L12: =+D12/D$21 -> 0.0021937293 | M12: =+E12/E$21 -> 0.0020699852 | N12: =+F12/F$21 -> 0.0021070742 | O12: =+G12/G$21 -> 0.0020817373 | R12: =RATE(5,0,-G12,B12) -> -0.0436475 | S12: =AVERAGE(T12:X12) -> -0.04209021 | T12: =(+B12-C12)/C12 -> -0.033816425 | U12: =(+C12-D12)/D12 -> -0.054794521 | V12: =(+D12-E12)/E12 -> 0.042857143 | W12: =(+E12-F12)/F12 -> -0.036697248 | X12: =(+F12-G12)/G12 -> -0.128
A13: Construction in progress | B13: =+B219 -> 1161 | C13: =+C219 -> 1002 | D13: =+D219 -> 792 | E13: =+E219 -> 1033 | F13: =+F219 -> 1165 | G13: =+G219 -> 1345 | J13: =+B13/B$21 -> 0.012826887 | K13: =+C13/C$21 -> 0.010728741 | L13: =+D13/D$21 -> 0.0079334869 | M13: =+E13/E$21 -> 0.010182356 | N13: =+F13/F$21 -> 0.011260282 | O13: =+G13/G$21 -> 0.011199747 | R13: =RATE(5,0,-G13,B13) -> -0.028993835 | S13: =AVERAGE(T13:X13) -> -0.011320126 | T13: =(+B13-C13)/C13 -> 0.15868263 | U13: =(+C13-D13)/D13 -> 0.26515152 | V13: =(+D13-E13)/E13 -> -0.23330106 | W13: =(+E13-F13)/F13 -> -0.11330472 | X13: =(+F13-G13)/G13 -> -0.133829
A14: Depreciable assets | B14: =+B220 -> 9591 | C14: =+C220 -> 9465 | D14: =+D220 -> 9428 | E14: =+E220 -> 8999 | F14: =+F220 -> 8279 | G14: =+G220 -> 7555 | J14: =+B14/B$21 -> 0.10596268 | K14: =+C14/C$21 -> 0.10134484 | L14: =+D14/D$21 -> 0.094440549 | M14: =+E14/E$21 -> 0.088703795 | N14: =+F14/F$21 -> 0.080020491 | O14: =+G14/G$21 -> 0.062910102 | R14: =RATE(5,0,-G14,B14) -> 0.048880193 | S14: =AVERAGE(T14:X14) -> 0.049541249 | T14: =(+B14-C14)/C14 -> 0.013312203 | U14: =(+C14-D14)/D14 -> 0.0039244803 | V14: =(+D14-E14)/E14 -> 0.047671964 | W14: =(+E14-F14)/F14 -> 0.086967025 | X14: =(+F14-G14)/G14 -> 0.095830576
A15: PP&E - at cost | B15: =+B221 -> 10952 | C15: =+C221 -> 10674 | D15: =+D221 -> 10439 | E15: =+E221 -> 10242 | F15: =+F221 -> 9662 | G15: =+G221 -> 9150 | J15: =+B15/B$21 -> 0.12099919 | K15: =+C15/C$21 -> 0.11429 | L15: =+D15/D$21 -> 0.10456777 | M15: =+E15/E$21 -> 0.10095614 | N15: =+F15/F$21 -> 0.093387847 | O15: =+G15/G$21 -> 0.076191586 | R15: =RATE(5,0,-G15,B15) -> 0.03660779 | S15: =AVERAGE(T15:X15) -> 0.036755223 | T15: =(+B15-C15)/C15 -> 0.026044594 | U15: =(+C15-D15)/D15 -> 0.022511735 | V15: =(+D15-E15)/E15 -> 0.019234525 | W15: =(+E15-F15)/F15 -> 0.06002898 | X15: =(+F15-G15)/G15 -> 0.055956284
A16: Accumulated depreciation | B16: =+B222 -> -4212 | C16: =+C222 -> -3868 | D16: =+D222 -> -3563 | E16: =+E222 -> -3187 | F16: =+F222 -> -2584 | G16: =+G222 -> -2089 | J16: =+B16/B$21 -> -0.046534752 | K16: =+C16/C$21 -> -0.041415937 | L16: =+D16/D$21 -> -0.035690674 | M16: =+E16/E$21 -> -0.03141449 | N16: =+F16/F$21 -> -0.024975595 | O16: =+G16/G$21 -> -0.017394997 | R16: =RATE(5,0,-G16,B16) -> 0.15056189 | S16: =AVERAGE(T16:X16) -> 0.15256616 | T16: =(+B16-C16)/C16 -> 0.08893485 | U16: =(+C16-D16)/D16 -> 0.085602021 | V16: =(+D16-E16)/E16 -> 0.11797929 | W16: =(+E16-F16)/F16 -> 0.23335913 | X16: =(+F16-G16)/G16 -> 0.23695548
A17: Property, plant & equipment - net | B17: 6740 | C17: 6806 | D17: 6876 | E17: 7055 | F17: 7078 | G17: 7061 | J17: =+B17/B$21 -> 0.074464442 | K17: =+C17/C$21 -> 0.07287406 | L17: =+D17/D$21 -> 0.068877091 | M17: =+E17/E$21 -> 0.069541646 | N17: =+F17/F$21 -> 0.068412252 | O17: =+G17/G$21 -> 0.058796589 | R17: =RATE(5,0,-G17,B17) -> -0.0092621911 | S17: =AVERAGE(T17:X17) -> -0.0092183309 | T17: =(+B17-C17)/C17 -> -0.0096973259 | U17: =(+C17-D17)/D17 -> -0.010180337 | V17: =(+D17-E17)/E17 -> -0.025372077 | W17: =(+E17-F17)/F17 -> -0.0032495055 | X17: =(+F17-G17)/G17 -> 0.002407591
A18: Right of Use assets | B18: =+B227 -> 668 | C18: =+C227 -> 569 | D18: =+D227 -> 562 | E18: =+E227 -> 542 | F18: =+F227 -> 0 | G18: =+G227 -> 0
A19: Goodwill and Intangibles (see detail) | B19: =+B244 -> 73482 | C19: =+C244 -> 74838 | D19: =+D244 -> 79756 | E19: =+E244 -> 84198 | F19: =+F244 -> 85971 | G19: =+G244 -> 104257 | J19: =+B19/B$21 -> 0.81183918 | K19: =+C19/C$21 -> 0.80131486 | L19: =+D19/D$21 -> 0.79891816 | M19: =+E19/E$21 -> 0.82994579 | N19: =+F19/F$21 -> 0.83095079 | O19: =+G19/G$21 -> 0.86814276 | R19: =RATE(5,0,-G19,B19) -> -0.067572339 | S19: =AVERAGE(T19:X19) -> -0.065711108 | T19: =(+B19-C19)/C19 -> -0.018119137 | U19: =(+C19-D19)/D19 -> -0.061663072 | V19: =(+D19-E19)/E19 -> -0.052756598 | W19: =(+E19-F19)/F19 -> -0.020623233 | X19: =(+F19-G19)/G19 -> -0.1753935
A20: Other assets | B20: =+B248 -> 1726 | C20: =+C248 -> 2187 | D20: =+D248 -> 1814 | E20: =+E248 -> 1558 | F20: =+F248 -> 1337 | G20: =+G248 -> 1573 | J20: =+B20/B$21 -> 0.019069084 | K20: =+C20/C$21 -> 0.023416922 | L20: =+D20/D$21 -> 0.018170891 | M20: =+E20/E$21 -> 0.015357319 | N20: =+F20/F$21 -> 0.012922744 | O20: =+G20/G$21 -> 0.013098291 | R20: =RATE(5,0,-G20,B20) -> 0.018737783 | S20: =AVERAGE(T20:X20) -> 0.034881754 | T20: =(+B20-C20)/C20 -> -0.21079104 | U20: =(+C20-D20)/D20 -> 0.20562293 | V20: =(+D20-E20)/E20 -> 0.16431322 | W20: =(+E20-F20)/F20 -> 0.16529544 | X20: =(+F20-G20)/G20 -> -0.15003179
A21: Total Assets | B21: =+B11+SUM(B17:B20) -> 90513 | C21: =+C11+SUM(C17:C20) -> 93394 | D21: =+D11+SUM(D17:D20) -> 99830 | E21: =+E11+SUM(E17:E20) -> 101450 | F21: =+F11+SUM(F17:F20) -> 103461 | G21: =+G11+SUM(G17:G20) -> 120092 | J21: =+B21/B$21 -> 1 | K21: =+C21/C$21 -> 1 | L21: =+D21/D$21 -> 1 | M21: =+E21/E$21 -> 1 | N21: =+F21/F$21 -> 1 | O21: =+G21/G$21 -> 1 | R21: =RATE(5,0,-G21,B21) -> -0.054983533 | S21: =AVERAGE(T21:X21) -> -0.053841726 | T21: =(+B21-C21)/C21 -> -0.030847806 | U21: =(+C21-D21)/D21 -> -0.064469598 | V21: =(+D21-E21)/E21 -> -0.015968457 | W21: =(+E21-F21)/F21 -> -0.019437276 | X21: =(+F21-G21)/G21 -> -0.13848549
A22: Liabilities and Equity
A23: Current Debt (see detail) | B23: =+B252 -> 837 | C23: =+C252 -> 754 | D23: =+D252 -> 236 | E23: =+E252 -> 1028 | F23: =+F252 -> 398 | G23: =+G252 -> 3195 | J23: =+B23/B$21 -> 0.0092472904 | K23: =+C23/C$21 -> 0.0080733238 | L23: =+D23/D$21 -> 0.0023640188 | M23: =+E23/E$21 -> 0.01013307 | N23: =+F23/F$21 -> 0.0038468602 | O23: =+G23/G$21 -> 0.026604603 | R23: =RATE(5,0,-G23,B23) -> -0.23501852 | S23: =AVERAGE(T23:X23) -> 0.44841021 | T23: =(+B23-C23)/C23 -> 0.11007958 | U23: =(+C23-D23)/D23 -> 2.1949153 | V23: =(+D23-E23)/E23 -> -0.77042802 | W23: =(+E23-F23)/F23 -> 1.5829146 | X23: =(+F23-G23)/G23 -> -0.87543036
A24: Trade payables | B24: 4848 | C24: 4753 | D24: 4304 | E24: 4003 | F24: 4153 | G24: 4362 | J24: =+B24/B$21 -> 0.053561367 | K24: =+C24/C$21 -> 0.05089192 | L24: =+D24/D$21 -> 0.043113293 | M24: =+E24/E$21 -> 0.039457861 | N24: =+F24/F$21 -> 0.040140729 | O24: =+G24/G$21 -> 0.036322153 | R24: =RATE(5,0,-G24,B24) -> 0.021351874 | S24: =AVERAGE(T24:X24) -> 0.023094055 | T24: =(+B24-C24)/C24 -> 0.019987376 | U24: =(+C24-D24)/D24 -> 0.10432156 | V24: =(+D24-E24)/E24 -> 0.075193605 | W24: =(+E24-F24)/F24 -> -0.036118469 | X24: =(+F24-G24)/G24 -> -0.047913801
A25: Deferred revenue | B25: 0 | C25: 0 | D25: 0 | E25: 0 | F25: 0 | G25: 0 | J25: =+B25/B$21 -> 0 | K25: =+C25/C$21 -> 0 | L25: =+D25/D$21 -> 0 | M25: =+E25/E$21 -> 0 | N25: =+F25/F$21 -> 0 | O25: =+G25/G$21 -> 0
A26: Current portion of operating lease liabilities | B26: =+B228 -> 125 | C26: =+C228 -> 133 | D26: =+D228 -> 135 | E26: =+E228 -> 147 | F26: =+F228 -> 0 | G26: =+G228 -> 0
A27: Other current liabilities (see detail) | B27: =+B260 -> 3218 | C27: =+C260 -> 3424 | D27: =+D260 -> 3386 | E27: =+E260 -> 2697 | F27: =+F260 -> 2952 | G27: =+G260 -> 2597 | J27: =+B27/B$21 -> 0.035552904 | K27: =+C27/C$21 -> 0.036661884 | L27: =+D27/D$21 -> 0.03391766 | M27: =+E27/E$21 -> 0.026584524 | N27: =+F27/F$21 -> 0.028532491 | O27: =+G27/G$21 -> 0.021625087 | R27: =RATE(5,0,-G27,B27) -> 0.04381328 | S27: =AVERAGE(T27:X27) -> 0.051368449 | T27: =(+B27-C27)/C27 -> -0.060163551 | U27: =(+C27-D27)/D27 -> 0.011222682 | V27: =(+D27-E27)/E27 -> 0.25546904 | W27: =(+E27-F27)/F27 -> -0.086382114 | X27: =(+F27-G27)/G27 -> 0.13669619
A28: Total current liabilities | B28: =SUM(B23:B27) -> 9028 | C28: =SUM(C23:C27) -> 9064 | D28: =SUM(D23:D27) -> 8061 | E28: =SUM(E23:E27) -> 7875 | F28: =SUM(F23:F27) -> 7503 | G28: =SUM(G23:G27) -> 10154 | J28: =+B28/B$21 -> 0.099742578 | K28: =+C28/C$21 -> 0.097051202 | L28: =+D28/D$21 -> 0.08074727 | M28: =+E28/E$21 -> 0.077624446 | N28: =+F28/F$21 -> 0.07252008 | O28: =+G28/G$21 -> 0.084551844 | R28: =RATE(5,0,-G28,B28) -> -0.023233226 | S28: =AVERAGE(T28:X28) -> -0.013485134 | T28: =(+B28-C28)/C28 -> -0.0039717564 | U28: =(+C28-D28)/D28 -> 0.12442625 | V28: =(+D28-E28)/E28 -> 0.023619048 | W28: =(+E28-F28)/F28 -> 0.049580168 | X28: =(+F28-G28)/G28 -> -0.26107938
A29: Long-term debt | B29: 19233 | C29: 21061 | D29: 28070 | E29: 28216 | F29: 30770 | G29: 28308 | J29: =+B29/B$21 -> 0.21248881 | K29: =+C29/C$21 -> 0.22550699 | L29: =+D29/D$21 -> 0.281178 | M29: =+E29/E$21 -> 0.27812716 | N29: =+F29/F$21 -> 0.29740675 | O29: =+G29/G$21 -> 0.23571928 | R29: =RATE(5,0,-G29,B29) -> -0.074391 | S29: =AVERAGE(T29:X29) -> -0.06753962 | T29: =(+B29-C29)/C29 -> -0.086795499 | U29: =(+C29-D29)/D29 -> -0.24969719 | V29: =(+D29-E29)/E29 -> -0.0051743692 | W29: =(+E29-F29)/F29 -> -0.083002925 | X29: =(+F29-G29)/G29 -> 0.086971881
A30: LT operating lease liabilities | B30: =+B229 -> 585 | C30: =+C229 -> 484 | D30: =+D229 -> 475 | E30: =+E229 -> 454 | F30: =+F229 -> 0 | G30: =+G229 -> 0
A31: Other non-current liabilities (see detail) | B31: =+B267 -> 12797 | C31: =+C267 -> 13333 | D31: =+D267 -> 12981 | E31: =+E267 -> 13156 | F31: =+F267 -> 13410 | G31: =+G267 -> 15554 | J31: =+B31/B$21 -> 0.14138301 | K31: =+C31/C$21 -> 0.14276078 | L31: =+D31/D$21 -> 0.13003105 | M31: =+E31/E$21 -> 0.12967965 | N31: =+F31/F$21 -> 0.12961406 | O31: =+G31/G$21 -> 0.12951737 | R31: =RATE(5,0,-G31,B31) -> -0.038269886 | S31: =AVERAGE(T31:X31) -> -0.036633962 | T31: =(+B31-C31)/C31 -> -0.040201005 | U31: =(+C31-D31)/D31 -> 0.027116555 | V31: =(+D31-E31)/E31 -> -0.013301915 | W31: =(+E31-F31)/F31 -> -0.018941089 | X31: =(+F31-G31)/G31 -> -0.13784236
A32: Total liabilities | B32: =SUM(B28:B31) -> 41643 | C32: =SUM(C28:C31) -> 43942 | D32: =SUM(D28:D31) -> 49587 | E32: =SUM(E28:E31) -> 49701 | F32: =SUM(F28:F31) -> 51683 | G32: =SUM(G28:G31) -> 54016 | J32: =+B32/B$21 -> 0.46007756 | K32: =+C32/C$21 -> 0.47050132 | L32: =+D32/D$21 -> 0.49671441 | M32: =+E32/E$21 -> 0.48990636 | N32: =+F32/F$21 -> 0.49954089 | O32: =+G32/G$21 -> 0.4497885 | R32: =RATE(5,0,-G32,B32) -> -0.050699045 | S32: =AVERAGE(T32:X32) -> -0.049998615 | T32: =(+B32-C32)/C32 -> -0.052318966 | U32: =(+C32-D32)/D32 -> -0.11384032 | V32: =(+D32-E32)/E32 -> -0.0022937164 | W32: =(+E32-F32)/F32 -> -0.038349167 | X32: =(+F32-G32)/G32 -> -0.043190906
A33: Redeemable Non-controlling interest | B33: 40 | C33: 4 | D33: 0 | E33: 0 | F33: 3 | G33: 6 | J33: =+B33/B$21 -> 0.00044192547 | K33: =+C33/C$21 -> 4.2829304e-05 | L33: =+D33/D$21 -> 0 | M33: =+E33/E$21 -> 0 | N33: =+F33/F$21 -> 2.8996433e-05 | O33: =+G33/G$21 -> 4.9961696e-05 | R33: =RATE(5,0,-G33,B33) -> 0.46144255 | S33: =AVERAGE(T33:X33) -> 2.5 | T33: =(+B33-C33)/C33 -> 9 | W33: =(+E33-F33)/F33 -> -1 | X33: =(+F33-G33)/G33 -> -0.5
A34: Total Equity | B34: =+B275 -> 48830 | C34: =+C275 -> 49448 | D34: =+D275 -> 50243 | E34: =+E275 -> 51749 | F34: =+F275 -> 51775 | G34: =+G275 -> 66070 | J34: =+B34/B$21 -> 0.53948052 | K34: =+C34/C$21 -> 0.52945585 | L34: =+D34/D$21 -> 0.50328559 | M34: =+E34/E$21 -> 0.51009364 | N34: =+F34/F$21 -> 0.50043011 | O34: =+G34/G$21 -> 0.55016154 | R34: =RATE(5,0,-G34,B34) -> -0.05868174 | S34: =AVERAGE(T34:X34) -> -0.054857339 | T34: =(+B34-C34)/C34 -> -0.012497978 | U34: =(+C34-D34)/D34 -> -0.0158231 | V34: =(+D34-E34)/E34 -> -0.029102012 | W34: =(+E34-F34)/F34 -> -0.00050217286 | X34: =(+F34-G34)/G34 -> -0.21636143
A35: Total Liabilities and Equity | B35: =+B34+B33+B32 -> 90513 | C35: =+C34+C33+C32 -> 93394 | D35: =+D34+D33+D32 -> 99830 | E35: =+E34+E33+E32 -> 101450 | F35: =+F34+F33+F32 -> 103461 | G35: =+G34+G33+G32 -> 120092 | J35: =+B35/B$21 -> 1 | K35: =+C35/C$21 -> 1 | L35: =+D35/D$21 -> 1 | M35: =+E35/E$21 -> 1 | N35: =+F35/F$21 -> 1 | O35: =+G35/G$21 -> 1 | R35: =RATE(5,0,-G35,B35) -> -0.054983533 | S35: =AVERAGE(T35:X35) -> -0.053841726 | T35: =(+B35-C35)/C35 -> -0.030847806 | U35: =(+C35-D35)/D35 -> -0.064469598 | V35: =(+D35-E35)/E35 -> -0.015968457 | W35: =(+E35-F35)/F35 -> -0.019437276 | X35: =(+F35-G35)/G35 -> -0.13848549
B36: =+B35-B21 -> 0 | C36: =+C35-C21 -> 0 | D36: =+D35-D21 -> 0 | E36: =+E35-E21 -> 0 | F36: =+F35-F21 -> 0 | G36: =+G35-G21 -> 0
A37: Shares issued | B37: 1243 | C37: 1235 | D37: 1228 | E37: 1224 | F37: 1224 | G37: 1221
A38: Treasury Shares | B38: -18 | C38: -11 | D38: -5 | E38: -3 | F38: -4 | G38: -2
A39: Shares Outstanding | B39: =+B37+B38 -> 1225 | C39: =+C37+C38 -> 1224 | D39: =+D37+D38 -> 1223 | E39: =+E37+E38 -> 1221 | F39: =+F37+F38 -> 1220 | G39: =+G37+G38 -> 1219
A40: Stock price at next 2/28 (60 days after FYE) | B40: 38.13 | C40: 39.22 | D40: 36.38 | E40: 24.77 | F40: 33.19 | G40: 67.14
...

Sheet Liquidity
A1: Kraft Heinz Company | B1: Reclassified
A2: Consolidated Balance Sheets
A3: in millions except per share data | F3: Late filing | G3: Restated
A4: Fiscal year ended 12/31: | B4: 2022 | C4: 2021 | D4: 2020 | E4: 2019 | F4: 2018 | G4: 2017
A5: Assets:
A6: Cash and equivalents | B6: 1040 | C6: 3445 | D6: 3417 | E6: 2279 | F6: 1130 | G6: 1629
A7: Marketable Securities | B7: 0 | C7: 0 | D7: 0 | E7: 0 | F7: 0 | G7: 0
A8: Trade receivables | B8: 2120 | C8: 1957 | D8: 2063 | E8: 1973 | F8: 2129 | G8: 921
A9: Inventories | B9: 3651 | C9: 2729 | D9: 2554 | E9: 2721 | F9: 2667 | G9: 2760
A10: Other current assets | B10: =+B276 -> 1086 | C10: =+C276 -> 863 | D10: =+D276 -> 2788 | E10: =+E276 -> 1124 | F10: =+F276 -> 3149 | G10: =+G276 -> 1891
A11: Total current assets | B11: =SUM(B6:B10) -> 7897 | C11: =SUM(C6:C10) -> 8994 | D11: =SUM(D6:D10) -> 10822 | E11: =SUM(E6:E10) -> 8097 | F11: =SUM(F6:F10) -> 9075 | G11: =SUM(G6:G10) -> 7201
A12: Land | B12: =+B254 -> 200 | C12: =+C254 -> 207 | D12: =+D254 -> 219 | E12: =+E254 -> 210 | F12: =+F254 -> 218 | G12: =+G254 -> 250
A13: Construction in progress | B13: =+B255 -> 1161 | C13: =+C255 -> 1002 | D13: =+D255 -> 792 | E13: =+E255 -> 1033 | F13: =+F255 -> 1165 | G13: =+G255 -> 1345
A14: Depreciable assets | B14: =+B256 -> 9591 | C14: =+C256 -> 9465 | D14: =+D256 -> 9428 | E14: =+E256 -> 8999 | F14: =+F256 -> 8279 | G14: =+G256 -> 7555
A15: PP&E - at cost | B15: =+B257 -> 10952 | C15: =+C257 -> 10674 | D15: =+D257 -> 10439 | E15: =+E257 -> 10242 | F15: =+F257 -> 9662 | G15: =+G257 -> 9150
A16: Accumulated depreciation | B16: =+B258 -> -4212 | C16: =+C258 -> -3868 | D16: =+D258 -> -3563 | E16: =+E258 -> -3187 | F16: =+F258 -> -2584 | G16: =+G258 -> -2089
A17: Property, plant & equipment - net | B17: 6740 | C17: 6806 | D17: 6876 | E17: 7055 | F17: 7078 | G17: 7061
A18: Right of Use assets | B18: =+B263 -> 668 | C18: =+C263 -> 569 | D18: =+D263 -> 562 | E18: =+E263 -> 542 | F18: =+F263 -> 0 | G18: =+G263 -> 0
A19: Goodwill and Intangibles (see detail) | B19: =+B280 -> 73482 | C19: =+C280 -> 74838 | D19: =+D280 -> 79756 | E19: =+E280 -> 84198 | F19: =+F280 -> 85971 | G19: =+G280 -> 104257
A20: Other assets | B20: =+B284 -> 1726 | C20: =+C284 -> 2187 | D20: =+D284 -> 1814 | E20: =+E284 -> 1558 | F20: =+F284 -> 1337 | G20: =+G284 -> 1573
A21: Total Assets | B21: =+B11+SUM(B17:B20) -> 90513 | C21: =+C11+SUM(C17:C20) -> 93394 | D21: =+D11+SUM(D17:D20) -> 99830 | E21: =+E11+SUM(E17:E20) -> 101450 | F21: =+F11+SUM(F17:F20) -> 103461 | G21: =+G11+SUM(G17:G20) -> 120092
A22: Liabilities and Equity
A23: Current Debt (see detail) | B23: =+B288 -> 837 | C23: =+C288 -> 754 | D23: =+D288 -> 236 | E23: =+E288 -> 1028 | F23: =+F288 -> 398 | G23: =+G288 -> 3195
A24: Trade payables | B24: 4848 | C24: 4753 | D24: 4304 | E24: 4003 | F24: 4153 | G24: 4362
A25: Deferred revenue | B25: 0 | C25: 0 | D25: 0 | E25: 0 | F25: 0 | G25: 0
A26: Current portion of operating lease liabilities | B26: =+B264 -> 125 | C26: =+C264 -> 133 | D26: =+D264 -> 135 | E26: =+E264 -> 147 | F26: =+F264 -> 0 | G26: =+G264 -> 0
A27: Other current liabilities (see detail) | B27: =+B296 -> 3218 | C27: =+C296 -> 3424 | D27: =+D296 -> 3386 | E27: =+E296 -> 2697 | F27: =+F296 -> 2952 | G27: =+G296 -> 2597
A28: Total current liabilities | B28: =SUM(B23:B27) -> 9028 | C28: =SUM(C23:C27) -> 9064 | D28: =SUM(D23:D27) -> 8061 | E28: =SUM(E23:E27) -> 7875 | F28: =SUM(F23:F27) -> 7503 | G28: =SUM(G23:G27) -> 10154
A29: Long-term debt | B29: 19233 | C29: 21061 | D29: 28070 | E29: 28216 | F29: 30770 | G29: 28308
A30: LT operating lease liabilities | B30: =+B265 -> 585 | C30: =+C265 -> 484 | D30: =+D265 -> 475 | E30: =+E265 -> 454 | F30: =+F265 -> 0 | G30: =+G265 -> 0
A31: Other non-current liabilities (see detail) | B31: =+B303 -> 12797 | C31: =+C303 -> 13333 | D31: =+D303 -> 12981 | E31: =+E303 -> 13156 | F31: =+F303 -> 13410 | G31: =+G303 -> 15554
